{
 "cells": [
  {
   "cell_type": "markdown",
   "metadata": {
    "colab_type": "text",
    "id": "68KCwL2AWHA0"
   },
   "source": [
    "## Initial setup"
   ]
  },
  {
   "cell_type": "code",
   "execution_count": null,
   "metadata": {},
   "outputs": [],
   "source": [
    "%pip install tensorflow==1.14 # Cáº§n python 3.6.*\n",
    "%pip install kaggle"
   ]
  },
  {
   "cell_type": "code",
   "execution_count": null,
   "metadata": {},
   "outputs": [],
   "source": [
    "import os\n",
    "import tempfile\n",
    "import json\n",
    "import tensorflow as tf"
   ]
  },
  {
   "cell_type": "code",
   "execution_count": 11,
   "metadata": {},
   "outputs": [
    {
     "name": "stdout",
     "output_type": "stream",
     "text": [
      "1.14.0\n"
     ]
    }
   ],
   "source": [
    "import tensorflow as tf\n",
    "print(tf.__version__)"
   ]
  },
  {
   "cell_type": "markdown",
   "metadata": {
    "colab_type": "text",
    "id": "3NWRdWuHXB0d"
   },
   "source": [
    "## Loading the checkpoints"
   ]
  },
  {
   "cell_type": "markdown",
   "metadata": {
    "colab_type": "text",
    "id": "1JQcwgXgKkBH"
   },
   "source": [
    "To use the Kaggle API, sign up for a Kaggle account at https://www.kaggle.com. Then go to the 'Account' tab of your user profile (https://www.kaggle.com/account) and select 'Create API Token'. This will trigger the download of `kaggle.json`, a file containing your API credentials."
   ]
  },
  {
   "cell_type": "code",
   "execution_count": null,
   "metadata": {},
   "outputs": [
    {
     "name": "stdout",
     "output_type": "stream",
     "text": [
      "Kaggle username: vantien03\n",
      "Kaggle API key set successfully\n"
     ]
    }
   ],
   "source": [
    "with open('./kaggle.json') as f:\n",
    "    credentials = json.load(f)\n",
    "    \n",
    "os.environ['KAGGLE_USERNAME'] = credentials['username']\n",
    "os.environ['KAGGLE_KEY'] = credentials['key']"
   ]
  },
  {
   "cell_type": "markdown",
   "metadata": {},
   "source": [
    "The U-GAT-IT authors provided the two checkpoints: one extracted after 50 epochs (~4.6GB) and the other extracted after 100 epochs (4.7GB). We will be using a much lighter version from Kaggle, that is suitable for mobile-based deployments."
   ]
  },
  {
   "cell_type": "code",
   "execution_count": null,
   "metadata": {
    "colab": {
     "base_uri": "https://localhost:8080/",
     "height": 68
    },
    "colab_type": "code",
    "id": "GxzhumMRXL2x",
    "outputId": "ae40676b-3408-46a8-9e28-d84294f01d2a"
   },
   "outputs": [],
   "source": [
    "!kaggle datasets download -d t04glovern/ugatit-selfie2anime-pretrained\n",
    "# unzip this zip file and change name folder to pretrained_model"
   ]
  },
  {
   "cell_type": "markdown",
   "metadata": {},
   "source": [
    "**Note**: There are other versions of the UGATIT model that you can check [here](https://github.com/taki0112/UGATIT/#pretrained-model). Here, we are using an optimized one. "
   ]
  },
  {
   "cell_type": "markdown",
   "metadata": {
    "colab_type": "text",
    "id": "EW9MMxaaXSbt"
   },
   "source": [
    "## Some utils"
   ]
  },
  {
   "cell_type": "code",
   "execution_count": null,
   "metadata": {},
   "outputs": [],
   "source": [
    "# git clone https://github.com/taki0112/UGATIT"
   ]
  },
  {
   "cell_type": "code",
   "execution_count": 2,
   "metadata": {
    "colab": {},
    "colab_type": "code",
    "id": "vFGKYLd-XX8d"
   },
   "outputs": [],
   "source": [
    "# Reference: https://dev.to/0xbf/use-dot-syntax-to-access-dictionary-key-python-tips-10ec\n",
    "class DictX(dict):\n",
    "    def __getattr__(self, key):\n",
    "        try:\n",
    "            return self[key]\n",
    "        except KeyError as k:\n",
    "            raise AttributeError(k)\n",
    "\n",
    "    def __setattr__(self, key, value):\n",
    "        self[key] = value\n",
    "\n",
    "    def __delattr__(self, key):\n",
    "        try:\n",
    "            del self[key]\n",
    "        except KeyError as k:\n",
    "            raise AttributeError(k)\n",
    "\n",
    "    def __repr__(self):\n",
    "        return '<DictX ' + dict.__repr__(self) + '>'"
   ]
  },
  {
   "cell_type": "code",
   "execution_count": 3,
   "metadata": {
    "colab": {},
    "colab_type": "code",
    "id": "1x062bvJXag7"
   },
   "outputs": [],
   "source": [
    "# This is needed just to initialize `UGATIT` class\n",
    "args = \tdict(phase='test',\n",
    "\tlight=True,\n",
    "\tdataset='selfie2anime',\n",
    "\tepoch=100,\n",
    "\titeration=10000,\n",
    "\tbatch_size=1,\n",
    "\tprint_freq=1000,\n",
    "\tsave_freq=1000,\n",
    "\tdecay_flag=True,\n",
    "\tdecay_epoch=50,\n",
    "\tlr=0.0001,\n",
    "\tGP_ld=10,\n",
    "\tadv_weight=1,\n",
    "\tcycle_weight=10,\n",
    "\tidentity_weight=10,\n",
    "\tcam_weight=1000,\n",
    "\tgan_type='lsgan',\n",
    "\tsmoothing=True,\n",
    "\tch=64,\n",
    "\tn_res=4,\n",
    "\tn_dis=6,\n",
    "\tn_critic=1,\n",
    "\tsn=True,\n",
    "\timg_size=256,\n",
    "\timg_ch=3,\n",
    "\taugment_flag=False,\n",
    "\tcheckpoint_dir='/pretrained_model',\n",
    "\tresult_dir='/pretrained_model',\n",
    "\tlog_dir='/pretrained_model',\n",
    "\tsample_dir='/pretrained_model')"
   ]
  },
  {
   "cell_type": "code",
   "execution_count": 4,
   "metadata": {
    "colab": {},
    "colab_type": "code",
    "id": "M_wRn12RXhLO"
   },
   "outputs": [],
   "source": [
    "# Wrap the arguments in a dictionary because this particular format is required \n",
    "# in order to instantiate the `UGATIT` class\n",
    "data = DictX(args)"
   ]
  },
  {
   "cell_type": "markdown",
   "metadata": {
    "colab_type": "text",
    "id": "vJAOonpvXwF6"
   },
   "source": [
    "## UGATIT class for convenience\n"
   ]
  },
  {
   "cell_type": "code",
   "execution_count": 5,
   "metadata": {},
   "outputs": [],
   "source": [
    "from UGATIT.UGATIT import UGATIT"
   ]
  },
  {
   "cell_type": "markdown",
   "metadata": {
    "colab_type": "text",
    "id": "UB6s-i19X4YD"
   },
   "source": [
    "## Build and initialize the model\n",
    "\n",
    "[Reference](https://github.com/tensorflow/magenta/blob/85ef5267513f62f4a40b01b2a1ee488f90f64a13/magenta/models/arbitrary_image_stylization/arbitrary_image_stylization_convert_tflite.py#L46) of the following utility. "
   ]
  },
  {
   "cell_type": "code",
   "execution_count": 6,
   "metadata": {
    "colab": {},
    "colab_type": "code",
    "id": "uUP3tXMJX2Yt"
   },
   "outputs": [],
   "source": [
    "def load_checkpoint(sess, checkpoint):\n",
    "  \"\"\"Loads a checkpoint file into the session.\n",
    "  Args:\n",
    "    sess: tf.Session, the TF session to load variables from the checkpoint to.\n",
    "    checkpoint: str, path to the checkpoint file.\n",
    "  \"\"\"\n",
    "  model_saver = tf.train.Saver(tf.global_variables())\n",
    "  checkpoint = os.path.expanduser(checkpoint)\n",
    "  if tf.gfile.IsDirectory(checkpoint):\n",
    "    checkpoint = tf.train.latest_checkpoint(checkpoint)\n",
    "    tf.logging.info('loading latest checkpoint file: {}'.format(checkpoint))\n",
    "  model_saver.restore(sess, checkpoint)"
   ]
  },
  {
   "cell_type": "markdown",
   "metadata": {
    "colab_type": "text",
    "id": "qSyn5u-oYb2s"
   },
   "source": [
    "## Exporting to `SavedModel`\n",
    "\n",
    "Note that we will only be using the `Selfie2Anime` variant. "
   ]
  },
  {
   "cell_type": "markdown",
   "metadata": {},
   "source": [
    "In our case, the input and the output tensors and their details can be accessed from an instance of the main model class. So, we will start by instantiating an instance of the UGATIT model class"
   ]
  },
  {
   "cell_type": "code",
   "execution_count": 8,
   "metadata": {
    "colab": {
     "base_uri": "https://localhost:8080/",
     "height": 1000
    },
    "colab_type": "code",
    "id": "ebgyMVAVYX0D",
    "outputId": "a2c6188b-a4ac-4c6b-9cfe-e4fb4628b713"
   },
   "outputs": [
    {
     "name": "stdout",
     "output_type": "stream",
     "text": [
      "\n",
      "##### Information #####\n",
      "# light :  True\n",
      "# gan type :  lsgan\n",
      "# dataset :  selfie2anime\n",
      "# max dataset number :  0\n",
      "# batch_size :  1\n",
      "# epoch :  100\n",
      "# iteration per epoch :  10000\n",
      "# smoothing :  True\n",
      "\n",
      "##### Generator #####\n",
      "# residual blocks :  4\n",
      "\n",
      "##### Discriminator #####\n",
      "# discriminator layer :  6\n",
      "# the number of critic :  1\n",
      "# spectral normalization :  True\n",
      "\n",
      "##### Weight #####\n",
      "# adv_weight :  1\n",
      "# cycle_weight :  10\n",
      "# identity_weight :  10\n",
      "# cam_weight :  1000\n",
      "WARNING:tensorflow:Entity <bound method Conv.call of <tensorflow.python.layers.convolutional.Conv2D object at 0x0000027E4DBE6940>> could not be transformed and will be executed as-is. Please report this to the AutgoGraph team. When filing the bug, set the verbosity to 10 (on Linux, `export AUTOGRAPH_VERBOSITY=10`) and attach the full output. Cause: converting <bound method Conv.call of <tensorflow.python.layers.convolutional.Conv2D object at 0x0000027E4DBE6940>>: AssertionError: Bad argument number for Name: 3, expecting 4\n",
      "WARNING: Entity <bound method Conv.call of <tensorflow.python.layers.convolutional.Conv2D object at 0x0000027E4DBE6940>> could not be transformed and will be executed as-is. Please report this to the AutgoGraph team. When filing the bug, set the verbosity to 10 (on Linux, `export AUTOGRAPH_VERBOSITY=10`) and attach the full output. Cause: converting <bound method Conv.call of <tensorflow.python.layers.convolutional.Conv2D object at 0x0000027E4DBE6940>>: AssertionError: Bad argument number for Name: 3, expecting 4\n",
      "WARNING:tensorflow:Entity <bound method Conv.call of <tensorflow.python.layers.convolutional.Conv2D object at 0x0000027E47AFF2B0>> could not be transformed and will be executed as-is. Please report this to the AutgoGraph team. When filing the bug, set the verbosity to 10 (on Linux, `export AUTOGRAPH_VERBOSITY=10`) and attach the full output. Cause: converting <bound method Conv.call of <tensorflow.python.layers.convolutional.Conv2D object at 0x0000027E47AFF2B0>>: AssertionError: Bad argument number for Name: 3, expecting 4\n",
      "WARNING: Entity <bound method Conv.call of <tensorflow.python.layers.convolutional.Conv2D object at 0x0000027E47AFF2B0>> could not be transformed and will be executed as-is. Please report this to the AutgoGraph team. When filing the bug, set the verbosity to 10 (on Linux, `export AUTOGRAPH_VERBOSITY=10`) and attach the full output. Cause: converting <bound method Conv.call of <tensorflow.python.layers.convolutional.Conv2D object at 0x0000027E47AFF2B0>>: AssertionError: Bad argument number for Name: 3, expecting 4\n",
      "WARNING:tensorflow:Entity <bound method Conv.call of <tensorflow.python.layers.convolutional.Conv2D object at 0x0000027E47AFF0F0>> could not be transformed and will be executed as-is. Please report this to the AutgoGraph team. When filing the bug, set the verbosity to 10 (on Linux, `export AUTOGRAPH_VERBOSITY=10`) and attach the full output. Cause: converting <bound method Conv.call of <tensorflow.python.layers.convolutional.Conv2D object at 0x0000027E47AFF0F0>>: AssertionError: Bad argument number for Name: 3, expecting 4\n",
      "WARNING: Entity <bound method Conv.call of <tensorflow.python.layers.convolutional.Conv2D object at 0x0000027E47AFF0F0>> could not be transformed and will be executed as-is. Please report this to the AutgoGraph team. When filing the bug, set the verbosity to 10 (on Linux, `export AUTOGRAPH_VERBOSITY=10`) and attach the full output. Cause: converting <bound method Conv.call of <tensorflow.python.layers.convolutional.Conv2D object at 0x0000027E47AFF0F0>>: AssertionError: Bad argument number for Name: 3, expecting 4\n",
      "WARNING:tensorflow:Entity <bound method Conv.call of <tensorflow.python.layers.convolutional.Conv2D object at 0x0000027E47AFD550>> could not be transformed and will be executed as-is. Please report this to the AutgoGraph team. When filing the bug, set the verbosity to 10 (on Linux, `export AUTOGRAPH_VERBOSITY=10`) and attach the full output. Cause: converting <bound method Conv.call of <tensorflow.python.layers.convolutional.Conv2D object at 0x0000027E47AFD550>>: AssertionError: Bad argument number for Name: 3, expecting 4\n",
      "WARNING: Entity <bound method Conv.call of <tensorflow.python.layers.convolutional.Conv2D object at 0x0000027E47AFD550>> could not be transformed and will be executed as-is. Please report this to the AutgoGraph team. When filing the bug, set the verbosity to 10 (on Linux, `export AUTOGRAPH_VERBOSITY=10`) and attach the full output. Cause: converting <bound method Conv.call of <tensorflow.python.layers.convolutional.Conv2D object at 0x0000027E47AFD550>>: AssertionError: Bad argument number for Name: 3, expecting 4\n",
      "WARNING:tensorflow:Entity <bound method Conv.call of <tensorflow.python.layers.convolutional.Conv2D object at 0x0000027E47AFD550>> could not be transformed and will be executed as-is. Please report this to the AutgoGraph team. When filing the bug, set the verbosity to 10 (on Linux, `export AUTOGRAPH_VERBOSITY=10`) and attach the full output. Cause: converting <bound method Conv.call of <tensorflow.python.layers.convolutional.Conv2D object at 0x0000027E47AFD550>>: AssertionError: Bad argument number for Name: 3, expecting 4\n",
      "WARNING: Entity <bound method Conv.call of <tensorflow.python.layers.convolutional.Conv2D object at 0x0000027E47AFD550>> could not be transformed and will be executed as-is. Please report this to the AutgoGraph team. When filing the bug, set the verbosity to 10 (on Linux, `export AUTOGRAPH_VERBOSITY=10`) and attach the full output. Cause: converting <bound method Conv.call of <tensorflow.python.layers.convolutional.Conv2D object at 0x0000027E47AFD550>>: AssertionError: Bad argument number for Name: 3, expecting 4\n",
      "WARNING:tensorflow:Entity <bound method Conv.call of <tensorflow.python.layers.convolutional.Conv2D object at 0x0000027E47BE9358>> could not be transformed and will be executed as-is. Please report this to the AutgoGraph team. When filing the bug, set the verbosity to 10 (on Linux, `export AUTOGRAPH_VERBOSITY=10`) and attach the full output. Cause: converting <bound method Conv.call of <tensorflow.python.layers.convolutional.Conv2D object at 0x0000027E47BE9358>>: AssertionError: Bad argument number for Name: 3, expecting 4\n",
      "WARNING: Entity <bound method Conv.call of <tensorflow.python.layers.convolutional.Conv2D object at 0x0000027E47BE9358>> could not be transformed and will be executed as-is. Please report this to the AutgoGraph team. When filing the bug, set the verbosity to 10 (on Linux, `export AUTOGRAPH_VERBOSITY=10`) and attach the full output. Cause: converting <bound method Conv.call of <tensorflow.python.layers.convolutional.Conv2D object at 0x0000027E47BE9358>>: AssertionError: Bad argument number for Name: 3, expecting 4\n",
      "WARNING:tensorflow:Entity <bound method Conv.call of <tensorflow.python.layers.convolutional.Conv2D object at 0x0000027E47AFD550>> could not be transformed and will be executed as-is. Please report this to the AutgoGraph team. When filing the bug, set the verbosity to 10 (on Linux, `export AUTOGRAPH_VERBOSITY=10`) and attach the full output. Cause: converting <bound method Conv.call of <tensorflow.python.layers.convolutional.Conv2D object at 0x0000027E47AFD550>>: AssertionError: Bad argument number for Name: 3, expecting 4\n",
      "WARNING: Entity <bound method Conv.call of <tensorflow.python.layers.convolutional.Conv2D object at 0x0000027E47AFD550>> could not be transformed and will be executed as-is. Please report this to the AutgoGraph team. When filing the bug, set the verbosity to 10 (on Linux, `export AUTOGRAPH_VERBOSITY=10`) and attach the full output. Cause: converting <bound method Conv.call of <tensorflow.python.layers.convolutional.Conv2D object at 0x0000027E47AFD550>>: AssertionError: Bad argument number for Name: 3, expecting 4\n",
      "WARNING:tensorflow:Entity <bound method Conv.call of <tensorflow.python.layers.convolutional.Conv2D object at 0x0000027E47BE9F28>> could not be transformed and will be executed as-is. Please report this to the AutgoGraph team. When filing the bug, set the verbosity to 10 (on Linux, `export AUTOGRAPH_VERBOSITY=10`) and attach the full output. Cause: converting <bound method Conv.call of <tensorflow.python.layers.convolutional.Conv2D object at 0x0000027E47BE9F28>>: AssertionError: Bad argument number for Name: 3, expecting 4\n",
      "WARNING: Entity <bound method Conv.call of <tensorflow.python.layers.convolutional.Conv2D object at 0x0000027E47BE9F28>> could not be transformed and will be executed as-is. Please report this to the AutgoGraph team. When filing the bug, set the verbosity to 10 (on Linux, `export AUTOGRAPH_VERBOSITY=10`) and attach the full output. Cause: converting <bound method Conv.call of <tensorflow.python.layers.convolutional.Conv2D object at 0x0000027E47BE9F28>>: AssertionError: Bad argument number for Name: 3, expecting 4\n",
      "WARNING:tensorflow:Entity <bound method Conv.call of <tensorflow.python.layers.convolutional.Conv2D object at 0x0000027E47CFBEF0>> could not be transformed and will be executed as-is. Please report this to the AutgoGraph team. When filing the bug, set the verbosity to 10 (on Linux, `export AUTOGRAPH_VERBOSITY=10`) and attach the full output. Cause: converting <bound method Conv.call of <tensorflow.python.layers.convolutional.Conv2D object at 0x0000027E47CFBEF0>>: AssertionError: Bad argument number for Name: 3, expecting 4\n",
      "WARNING: Entity <bound method Conv.call of <tensorflow.python.layers.convolutional.Conv2D object at 0x0000027E47CFBEF0>> could not be transformed and will be executed as-is. Please report this to the AutgoGraph team. When filing the bug, set the verbosity to 10 (on Linux, `export AUTOGRAPH_VERBOSITY=10`) and attach the full output. Cause: converting <bound method Conv.call of <tensorflow.python.layers.convolutional.Conv2D object at 0x0000027E47CFBEF0>>: AssertionError: Bad argument number for Name: 3, expecting 4\n",
      "WARNING:tensorflow:Entity <bound method Conv.call of <tensorflow.python.layers.convolutional.Conv2D object at 0x0000027E47CFBEF0>> could not be transformed and will be executed as-is. Please report this to the AutgoGraph team. When filing the bug, set the verbosity to 10 (on Linux, `export AUTOGRAPH_VERBOSITY=10`) and attach the full output. Cause: converting <bound method Conv.call of <tensorflow.python.layers.convolutional.Conv2D object at 0x0000027E47CFBEF0>>: AssertionError: Bad argument number for Name: 3, expecting 4\n",
      "WARNING: Entity <bound method Conv.call of <tensorflow.python.layers.convolutional.Conv2D object at 0x0000027E47CFBEF0>> could not be transformed and will be executed as-is. Please report this to the AutgoGraph team. When filing the bug, set the verbosity to 10 (on Linux, `export AUTOGRAPH_VERBOSITY=10`) and attach the full output. Cause: converting <bound method Conv.call of <tensorflow.python.layers.convolutional.Conv2D object at 0x0000027E47CFBEF0>>: AssertionError: Bad argument number for Name: 3, expecting 4\n",
      "WARNING:tensorflow:Entity <bound method Conv.call of <tensorflow.python.layers.convolutional.Conv2D object at 0x0000027E47E1EFD0>> could not be transformed and will be executed as-is. Please report this to the AutgoGraph team. When filing the bug, set the verbosity to 10 (on Linux, `export AUTOGRAPH_VERBOSITY=10`) and attach the full output. Cause: converting <bound method Conv.call of <tensorflow.python.layers.convolutional.Conv2D object at 0x0000027E47E1EFD0>>: AssertionError: Bad argument number for Name: 3, expecting 4\n",
      "WARNING: Entity <bound method Conv.call of <tensorflow.python.layers.convolutional.Conv2D object at 0x0000027E47E1EFD0>> could not be transformed and will be executed as-is. Please report this to the AutgoGraph team. When filing the bug, set the verbosity to 10 (on Linux, `export AUTOGRAPH_VERBOSITY=10`) and attach the full output. Cause: converting <bound method Conv.call of <tensorflow.python.layers.convolutional.Conv2D object at 0x0000027E47E1EFD0>>: AssertionError: Bad argument number for Name: 3, expecting 4\n",
      "WARNING:tensorflow:Entity <bound method Flatten.call of <tensorflow.python.layers.core.Flatten object at 0x0000027E47AFF2B0>> could not be transformed and will be executed as-is. Please report this to the AutgoGraph team. When filing the bug, set the verbosity to 10 (on Linux, `export AUTOGRAPH_VERBOSITY=10`) and attach the full output. Cause: converting <bound method Flatten.call of <tensorflow.python.layers.core.Flatten object at 0x0000027E47AFF2B0>>: AttributeError: module 'gast' has no attribute 'Num'\n",
      "WARNING: Entity <bound method Flatten.call of <tensorflow.python.layers.core.Flatten object at 0x0000027E47AFF2B0>> could not be transformed and will be executed as-is. Please report this to the AutgoGraph team. When filing the bug, set the verbosity to 10 (on Linux, `export AUTOGRAPH_VERBOSITY=10`) and attach the full output. Cause: converting <bound method Flatten.call of <tensorflow.python.layers.core.Flatten object at 0x0000027E47AFF2B0>>: AttributeError: module 'gast' has no attribute 'Num'\n",
      "WARNING:tensorflow:Entity <bound method Flatten.call of <tensorflow.python.layers.core.Flatten object at 0x0000027E47B0E7F0>> could not be transformed and will be executed as-is. Please report this to the AutgoGraph team. When filing the bug, set the verbosity to 10 (on Linux, `export AUTOGRAPH_VERBOSITY=10`) and attach the full output. Cause: converting <bound method Flatten.call of <tensorflow.python.layers.core.Flatten object at 0x0000027E47B0E7F0>>: AttributeError: module 'gast' has no attribute 'Num'\n",
      "WARNING: Entity <bound method Flatten.call of <tensorflow.python.layers.core.Flatten object at 0x0000027E47B0E7F0>> could not be transformed and will be executed as-is. Please report this to the AutgoGraph team. When filing the bug, set the verbosity to 10 (on Linux, `export AUTOGRAPH_VERBOSITY=10`) and attach the full output. Cause: converting <bound method Flatten.call of <tensorflow.python.layers.core.Flatten object at 0x0000027E47B0E7F0>>: AttributeError: module 'gast' has no attribute 'Num'\n",
      "WARNING:tensorflow:Entity <bound method Conv.call of <tensorflow.python.layers.convolutional.Conv2D object at 0x0000027E47F18630>> could not be transformed and will be executed as-is. Please report this to the AutgoGraph team. When filing the bug, set the verbosity to 10 (on Linux, `export AUTOGRAPH_VERBOSITY=10`) and attach the full output. Cause: converting <bound method Conv.call of <tensorflow.python.layers.convolutional.Conv2D object at 0x0000027E47F18630>>: AssertionError: Bad argument number for Name: 3, expecting 4\n",
      "WARNING: Entity <bound method Conv.call of <tensorflow.python.layers.convolutional.Conv2D object at 0x0000027E47F18630>> could not be transformed and will be executed as-is. Please report this to the AutgoGraph team. When filing the bug, set the verbosity to 10 (on Linux, `export AUTOGRAPH_VERBOSITY=10`) and attach the full output. Cause: converting <bound method Conv.call of <tensorflow.python.layers.convolutional.Conv2D object at 0x0000027E47F18630>>: AssertionError: Bad argument number for Name: 3, expecting 4\n",
      "WARNING:tensorflow:Entity <bound method Flatten.call of <tensorflow.python.layers.core.Flatten object at 0x0000027E47FF9A58>> could not be transformed and will be executed as-is. Please report this to the AutgoGraph team. When filing the bug, set the verbosity to 10 (on Linux, `export AUTOGRAPH_VERBOSITY=10`) and attach the full output. Cause: converting <bound method Flatten.call of <tensorflow.python.layers.core.Flatten object at 0x0000027E47FF9A58>>: AttributeError: module 'gast' has no attribute 'Num'\n",
      "WARNING: Entity <bound method Flatten.call of <tensorflow.python.layers.core.Flatten object at 0x0000027E47FF9A58>> could not be transformed and will be executed as-is. Please report this to the AutgoGraph team. When filing the bug, set the verbosity to 10 (on Linux, `export AUTOGRAPH_VERBOSITY=10`) and attach the full output. Cause: converting <bound method Flatten.call of <tensorflow.python.layers.core.Flatten object at 0x0000027E47FF9A58>>: AttributeError: module 'gast' has no attribute 'Num'\n",
      "WARNING:tensorflow:Entity <bound method Dense.call of <tensorflow.python.layers.core.Dense object at 0x0000027E47FDCE48>> could not be transformed and will be executed as-is. Please report this to the AutgoGraph team. When filing the bug, set the verbosity to 10 (on Linux, `export AUTOGRAPH_VERBOSITY=10`) and attach the full output. Cause: converting <bound method Dense.call of <tensorflow.python.layers.core.Dense object at 0x0000027E47FDCE48>>: AssertionError: Bad argument number for Name: 3, expecting 4\n",
      "WARNING: Entity <bound method Dense.call of <tensorflow.python.layers.core.Dense object at 0x0000027E47FDCE48>> could not be transformed and will be executed as-is. Please report this to the AutgoGraph team. When filing the bug, set the verbosity to 10 (on Linux, `export AUTOGRAPH_VERBOSITY=10`) and attach the full output. Cause: converting <bound method Dense.call of <tensorflow.python.layers.core.Dense object at 0x0000027E47FDCE48>>: AssertionError: Bad argument number for Name: 3, expecting 4\n",
      "WARNING:tensorflow:Entity <bound method Flatten.call of <tensorflow.python.layers.core.Flatten object at 0x0000027E44A082B0>> could not be transformed and will be executed as-is. Please report this to the AutgoGraph team. When filing the bug, set the verbosity to 10 (on Linux, `export AUTOGRAPH_VERBOSITY=10`) and attach the full output. Cause: converting <bound method Flatten.call of <tensorflow.python.layers.core.Flatten object at 0x0000027E44A082B0>>: AttributeError: module 'gast' has no attribute 'Num'\n",
      "WARNING: Entity <bound method Flatten.call of <tensorflow.python.layers.core.Flatten object at 0x0000027E44A082B0>> could not be transformed and will be executed as-is. Please report this to the AutgoGraph team. When filing the bug, set the verbosity to 10 (on Linux, `export AUTOGRAPH_VERBOSITY=10`) and attach the full output. Cause: converting <bound method Flatten.call of <tensorflow.python.layers.core.Flatten object at 0x0000027E44A082B0>>: AttributeError: module 'gast' has no attribute 'Num'\n",
      "WARNING:tensorflow:Entity <bound method Dense.call of <tensorflow.python.layers.core.Dense object at 0x0000027E4463ED30>> could not be transformed and will be executed as-is. Please report this to the AutgoGraph team. When filing the bug, set the verbosity to 10 (on Linux, `export AUTOGRAPH_VERBOSITY=10`) and attach the full output. Cause: converting <bound method Dense.call of <tensorflow.python.layers.core.Dense object at 0x0000027E4463ED30>>: AssertionError: Bad argument number for Name: 3, expecting 4\n",
      "WARNING: Entity <bound method Dense.call of <tensorflow.python.layers.core.Dense object at 0x0000027E4463ED30>> could not be transformed and will be executed as-is. Please report this to the AutgoGraph team. When filing the bug, set the verbosity to 10 (on Linux, `export AUTOGRAPH_VERBOSITY=10`) and attach the full output. Cause: converting <bound method Dense.call of <tensorflow.python.layers.core.Dense object at 0x0000027E4463ED30>>: AssertionError: Bad argument number for Name: 3, expecting 4\n",
      "WARNING:tensorflow:Entity <bound method Flatten.call of <tensorflow.python.layers.core.Flatten object at 0x0000027E4463ED30>> could not be transformed and will be executed as-is. Please report this to the AutgoGraph team. When filing the bug, set the verbosity to 10 (on Linux, `export AUTOGRAPH_VERBOSITY=10`) and attach the full output. Cause: converting <bound method Flatten.call of <tensorflow.python.layers.core.Flatten object at 0x0000027E4463ED30>>: AttributeError: module 'gast' has no attribute 'Num'\n",
      "WARNING: Entity <bound method Flatten.call of <tensorflow.python.layers.core.Flatten object at 0x0000027E4463ED30>> could not be transformed and will be executed as-is. Please report this to the AutgoGraph team. When filing the bug, set the verbosity to 10 (on Linux, `export AUTOGRAPH_VERBOSITY=10`) and attach the full output. Cause: converting <bound method Flatten.call of <tensorflow.python.layers.core.Flatten object at 0x0000027E4463ED30>>: AttributeError: module 'gast' has no attribute 'Num'\n",
      "WARNING:tensorflow:Entity <bound method Dense.call of <tensorflow.python.layers.core.Dense object at 0x0000027E47FDC5C0>> could not be transformed and will be executed as-is. Please report this to the AutgoGraph team. When filing the bug, set the verbosity to 10 (on Linux, `export AUTOGRAPH_VERBOSITY=10`) and attach the full output. Cause: converting <bound method Dense.call of <tensorflow.python.layers.core.Dense object at 0x0000027E47FDC5C0>>: AssertionError: Bad argument number for Name: 3, expecting 4\n",
      "WARNING: Entity <bound method Dense.call of <tensorflow.python.layers.core.Dense object at 0x0000027E47FDC5C0>> could not be transformed and will be executed as-is. Please report this to the AutgoGraph team. When filing the bug, set the verbosity to 10 (on Linux, `export AUTOGRAPH_VERBOSITY=10`) and attach the full output. Cause: converting <bound method Dense.call of <tensorflow.python.layers.core.Dense object at 0x0000027E47FDC5C0>>: AssertionError: Bad argument number for Name: 3, expecting 4\n",
      "WARNING:tensorflow:Entity <bound method Flatten.call of <tensorflow.python.layers.core.Flatten object at 0x0000027E47FDCBE0>> could not be transformed and will be executed as-is. Please report this to the AutgoGraph team. When filing the bug, set the verbosity to 10 (on Linux, `export AUTOGRAPH_VERBOSITY=10`) and attach the full output. Cause: converting <bound method Flatten.call of <tensorflow.python.layers.core.Flatten object at 0x0000027E47FDCBE0>>: AttributeError: module 'gast' has no attribute 'Num'\n",
      "WARNING: Entity <bound method Flatten.call of <tensorflow.python.layers.core.Flatten object at 0x0000027E47FDCBE0>> could not be transformed and will be executed as-is. Please report this to the AutgoGraph team. When filing the bug, set the verbosity to 10 (on Linux, `export AUTOGRAPH_VERBOSITY=10`) and attach the full output. Cause: converting <bound method Flatten.call of <tensorflow.python.layers.core.Flatten object at 0x0000027E47FDCBE0>>: AttributeError: module 'gast' has no attribute 'Num'\n",
      "WARNING:tensorflow:Entity <bound method Dense.call of <tensorflow.python.layers.core.Dense object at 0x0000027E47FDCC50>> could not be transformed and will be executed as-is. Please report this to the AutgoGraph team. When filing the bug, set the verbosity to 10 (on Linux, `export AUTOGRAPH_VERBOSITY=10`) and attach the full output. Cause: converting <bound method Dense.call of <tensorflow.python.layers.core.Dense object at 0x0000027E47FDCC50>>: AssertionError: Bad argument number for Name: 3, expecting 4\n",
      "WARNING: Entity <bound method Dense.call of <tensorflow.python.layers.core.Dense object at 0x0000027E47FDCC50>> could not be transformed and will be executed as-is. Please report this to the AutgoGraph team. When filing the bug, set the verbosity to 10 (on Linux, `export AUTOGRAPH_VERBOSITY=10`) and attach the full output. Cause: converting <bound method Dense.call of <tensorflow.python.layers.core.Dense object at 0x0000027E47FDCC50>>: AssertionError: Bad argument number for Name: 3, expecting 4\n",
      "WARNING:tensorflow:Entity <bound method Conv.call of <tensorflow.python.layers.convolutional.Conv2D object at 0x0000027E47FDC5C0>> could not be transformed and will be executed as-is. Please report this to the AutgoGraph team. When filing the bug, set the verbosity to 10 (on Linux, `export AUTOGRAPH_VERBOSITY=10`) and attach the full output. Cause: converting <bound method Conv.call of <tensorflow.python.layers.convolutional.Conv2D object at 0x0000027E47FDC5C0>>: AssertionError: Bad argument number for Name: 3, expecting 4\n",
      "WARNING: Entity <bound method Conv.call of <tensorflow.python.layers.convolutional.Conv2D object at 0x0000027E47FDC5C0>> could not be transformed and will be executed as-is. Please report this to the AutgoGraph team. When filing the bug, set the verbosity to 10 (on Linux, `export AUTOGRAPH_VERBOSITY=10`) and attach the full output. Cause: converting <bound method Conv.call of <tensorflow.python.layers.convolutional.Conv2D object at 0x0000027E47FDC5C0>>: AssertionError: Bad argument number for Name: 3, expecting 4\n",
      "WARNING:tensorflow:Entity <bound method Conv.call of <tensorflow.python.layers.convolutional.Conv2D object at 0x0000027E480442E8>> could not be transformed and will be executed as-is. Please report this to the AutgoGraph team. When filing the bug, set the verbosity to 10 (on Linux, `export AUTOGRAPH_VERBOSITY=10`) and attach the full output. Cause: converting <bound method Conv.call of <tensorflow.python.layers.convolutional.Conv2D object at 0x0000027E480442E8>>: AssertionError: Bad argument number for Name: 3, expecting 4\n",
      "WARNING: Entity <bound method Conv.call of <tensorflow.python.layers.convolutional.Conv2D object at 0x0000027E480442E8>> could not be transformed and will be executed as-is. Please report this to the AutgoGraph team. When filing the bug, set the verbosity to 10 (on Linux, `export AUTOGRAPH_VERBOSITY=10`) and attach the full output. Cause: converting <bound method Conv.call of <tensorflow.python.layers.convolutional.Conv2D object at 0x0000027E480442E8>>: AssertionError: Bad argument number for Name: 3, expecting 4\n",
      "WARNING:tensorflow:Entity <bound method Conv.call of <tensorflow.python.layers.convolutional.Conv2D object at 0x0000027E48109080>> could not be transformed and will be executed as-is. Please report this to the AutgoGraph team. When filing the bug, set the verbosity to 10 (on Linux, `export AUTOGRAPH_VERBOSITY=10`) and attach the full output. Cause: converting <bound method Conv.call of <tensorflow.python.layers.convolutional.Conv2D object at 0x0000027E48109080>>: AssertionError: Bad argument number for Name: 3, expecting 4\n",
      "WARNING: Entity <bound method Conv.call of <tensorflow.python.layers.convolutional.Conv2D object at 0x0000027E48109080>> could not be transformed and will be executed as-is. Please report this to the AutgoGraph team. When filing the bug, set the verbosity to 10 (on Linux, `export AUTOGRAPH_VERBOSITY=10`) and attach the full output. Cause: converting <bound method Conv.call of <tensorflow.python.layers.convolutional.Conv2D object at 0x0000027E48109080>>: AssertionError: Bad argument number for Name: 3, expecting 4\n",
      "WARNING:tensorflow:Entity <bound method Conv.call of <tensorflow.python.layers.convolutional.Conv2D object at 0x0000027E481A6438>> could not be transformed and will be executed as-is. Please report this to the AutgoGraph team. When filing the bug, set the verbosity to 10 (on Linux, `export AUTOGRAPH_VERBOSITY=10`) and attach the full output. Cause: converting <bound method Conv.call of <tensorflow.python.layers.convolutional.Conv2D object at 0x0000027E481A6438>>: AssertionError: Bad argument number for Name: 3, expecting 4\n",
      "WARNING: Entity <bound method Conv.call of <tensorflow.python.layers.convolutional.Conv2D object at 0x0000027E481A6438>> could not be transformed and will be executed as-is. Please report this to the AutgoGraph team. When filing the bug, set the verbosity to 10 (on Linux, `export AUTOGRAPH_VERBOSITY=10`) and attach the full output. Cause: converting <bound method Conv.call of <tensorflow.python.layers.convolutional.Conv2D object at 0x0000027E481A6438>>: AssertionError: Bad argument number for Name: 3, expecting 4\n",
      "WARNING:tensorflow:Entity <bound method Conv.call of <tensorflow.python.layers.convolutional.Conv2D object at 0x0000027E48044F98>> could not be transformed and will be executed as-is. Please report this to the AutgoGraph team. When filing the bug, set the verbosity to 10 (on Linux, `export AUTOGRAPH_VERBOSITY=10`) and attach the full output. Cause: converting <bound method Conv.call of <tensorflow.python.layers.convolutional.Conv2D object at 0x0000027E48044F98>>: AssertionError: Bad argument number for Name: 3, expecting 4\n",
      "WARNING: Entity <bound method Conv.call of <tensorflow.python.layers.convolutional.Conv2D object at 0x0000027E48044F98>> could not be transformed and will be executed as-is. Please report this to the AutgoGraph team. When filing the bug, set the verbosity to 10 (on Linux, `export AUTOGRAPH_VERBOSITY=10`) and attach the full output. Cause: converting <bound method Conv.call of <tensorflow.python.layers.convolutional.Conv2D object at 0x0000027E48044F98>>: AssertionError: Bad argument number for Name: 3, expecting 4\n",
      "WARNING:tensorflow:Entity <bound method Conv.call of <tensorflow.python.layers.convolutional.Conv2D object at 0x0000027E4823A668>> could not be transformed and will be executed as-is. Please report this to the AutgoGraph team. When filing the bug, set the verbosity to 10 (on Linux, `export AUTOGRAPH_VERBOSITY=10`) and attach the full output. Cause: converting <bound method Conv.call of <tensorflow.python.layers.convolutional.Conv2D object at 0x0000027E4823A668>>: AssertionError: Bad argument number for Name: 3, expecting 4\n",
      "WARNING: Entity <bound method Conv.call of <tensorflow.python.layers.convolutional.Conv2D object at 0x0000027E4823A668>> could not be transformed and will be executed as-is. Please report this to the AutgoGraph team. When filing the bug, set the verbosity to 10 (on Linux, `export AUTOGRAPH_VERBOSITY=10`) and attach the full output. Cause: converting <bound method Conv.call of <tensorflow.python.layers.convolutional.Conv2D object at 0x0000027E4823A668>>: AssertionError: Bad argument number for Name: 3, expecting 4\n",
      "WARNING:tensorflow:Entity <bound method Conv.call of <tensorflow.python.layers.convolutional.Conv2D object at 0x0000027E4823A668>> could not be transformed and will be executed as-is. Please report this to the AutgoGraph team. When filing the bug, set the verbosity to 10 (on Linux, `export AUTOGRAPH_VERBOSITY=10`) and attach the full output. Cause: converting <bound method Conv.call of <tensorflow.python.layers.convolutional.Conv2D object at 0x0000027E4823A668>>: AssertionError: Bad argument number for Name: 3, expecting 4\n",
      "WARNING: Entity <bound method Conv.call of <tensorflow.python.layers.convolutional.Conv2D object at 0x0000027E4823A668>> could not be transformed and will be executed as-is. Please report this to the AutgoGraph team. When filing the bug, set the verbosity to 10 (on Linux, `export AUTOGRAPH_VERBOSITY=10`) and attach the full output. Cause: converting <bound method Conv.call of <tensorflow.python.layers.convolutional.Conv2D object at 0x0000027E4823A668>>: AssertionError: Bad argument number for Name: 3, expecting 4\n",
      "WARNING:tensorflow:Entity <bound method Conv.call of <tensorflow.python.layers.convolutional.Conv2D object at 0x0000027E483D92B0>> could not be transformed and will be executed as-is. Please report this to the AutgoGraph team. When filing the bug, set the verbosity to 10 (on Linux, `export AUTOGRAPH_VERBOSITY=10`) and attach the full output. Cause: converting <bound method Conv.call of <tensorflow.python.layers.convolutional.Conv2D object at 0x0000027E483D92B0>>: AssertionError: Bad argument number for Name: 3, expecting 4\n",
      "WARNING: Entity <bound method Conv.call of <tensorflow.python.layers.convolutional.Conv2D object at 0x0000027E483D92B0>> could not be transformed and will be executed as-is. Please report this to the AutgoGraph team. When filing the bug, set the verbosity to 10 (on Linux, `export AUTOGRAPH_VERBOSITY=10`) and attach the full output. Cause: converting <bound method Conv.call of <tensorflow.python.layers.convolutional.Conv2D object at 0x0000027E483D92B0>>: AssertionError: Bad argument number for Name: 3, expecting 4\n",
      "WARNING:tensorflow:Entity <bound method Conv.call of <tensorflow.python.layers.convolutional.Conv2D object at 0x0000027E47FF9240>> could not be transformed and will be executed as-is. Please report this to the AutgoGraph team. When filing the bug, set the verbosity to 10 (on Linux, `export AUTOGRAPH_VERBOSITY=10`) and attach the full output. Cause: converting <bound method Conv.call of <tensorflow.python.layers.convolutional.Conv2D object at 0x0000027E47FF9240>>: AssertionError: Bad argument number for Name: 3, expecting 4\n",
      "WARNING: Entity <bound method Conv.call of <tensorflow.python.layers.convolutional.Conv2D object at 0x0000027E47FF9240>> could not be transformed and will be executed as-is. Please report this to the AutgoGraph team. When filing the bug, set the verbosity to 10 (on Linux, `export AUTOGRAPH_VERBOSITY=10`) and attach the full output. Cause: converting <bound method Conv.call of <tensorflow.python.layers.convolutional.Conv2D object at 0x0000027E47FF9240>>: AssertionError: Bad argument number for Name: 3, expecting 4\n",
      "WARNING:tensorflow:Entity <bound method Conv.call of <tensorflow.python.layers.convolutional.Conv2D object at 0x0000027E47AFF978>> could not be transformed and will be executed as-is. Please report this to the AutgoGraph team. When filing the bug, set the verbosity to 10 (on Linux, `export AUTOGRAPH_VERBOSITY=10`) and attach the full output. Cause: converting <bound method Conv.call of <tensorflow.python.layers.convolutional.Conv2D object at 0x0000027E47AFF978>>: AssertionError: Bad argument number for Name: 3, expecting 4\n",
      "WARNING: Entity <bound method Conv.call of <tensorflow.python.layers.convolutional.Conv2D object at 0x0000027E47AFF978>> could not be transformed and will be executed as-is. Please report this to the AutgoGraph team. When filing the bug, set the verbosity to 10 (on Linux, `export AUTOGRAPH_VERBOSITY=10`) and attach the full output. Cause: converting <bound method Conv.call of <tensorflow.python.layers.convolutional.Conv2D object at 0x0000027E47AFF978>>: AssertionError: Bad argument number for Name: 3, expecting 4\n",
      "WARNING:tensorflow:Entity <bound method Conv.call of <tensorflow.python.layers.convolutional.Conv2D object at 0x0000027E484FCF98>> could not be transformed and will be executed as-is. Please report this to the AutgoGraph team. When filing the bug, set the verbosity to 10 (on Linux, `export AUTOGRAPH_VERBOSITY=10`) and attach the full output. Cause: converting <bound method Conv.call of <tensorflow.python.layers.convolutional.Conv2D object at 0x0000027E484FCF98>>: AssertionError: Bad argument number for Name: 3, expecting 4\n",
      "WARNING: Entity <bound method Conv.call of <tensorflow.python.layers.convolutional.Conv2D object at 0x0000027E484FCF98>> could not be transformed and will be executed as-is. Please report this to the AutgoGraph team. When filing the bug, set the verbosity to 10 (on Linux, `export AUTOGRAPH_VERBOSITY=10`) and attach the full output. Cause: converting <bound method Conv.call of <tensorflow.python.layers.convolutional.Conv2D object at 0x0000027E484FCF98>>: AssertionError: Bad argument number for Name: 3, expecting 4\n",
      "WARNING:tensorflow:Entity <bound method Conv.call of <tensorflow.python.layers.convolutional.Conv2D object at 0x0000027E4DBE6470>> could not be transformed and will be executed as-is. Please report this to the AutgoGraph team. When filing the bug, set the verbosity to 10 (on Linux, `export AUTOGRAPH_VERBOSITY=10`) and attach the full output. Cause: converting <bound method Conv.call of <tensorflow.python.layers.convolutional.Conv2D object at 0x0000027E4DBE6470>>: AssertionError: Bad argument number for Name: 3, expecting 4\n",
      "WARNING: Entity <bound method Conv.call of <tensorflow.python.layers.convolutional.Conv2D object at 0x0000027E4DBE6470>> could not be transformed and will be executed as-is. Please report this to the AutgoGraph team. When filing the bug, set the verbosity to 10 (on Linux, `export AUTOGRAPH_VERBOSITY=10`) and attach the full output. Cause: converting <bound method Conv.call of <tensorflow.python.layers.convolutional.Conv2D object at 0x0000027E4DBE6470>>: AssertionError: Bad argument number for Name: 3, expecting 4\n",
      "WARNING:tensorflow:Entity <bound method Conv.call of <tensorflow.python.layers.convolutional.Conv2D object at 0x0000027E43F5A3C8>> could not be transformed and will be executed as-is. Please report this to the AutgoGraph team. When filing the bug, set the verbosity to 10 (on Linux, `export AUTOGRAPH_VERBOSITY=10`) and attach the full output. Cause: converting <bound method Conv.call of <tensorflow.python.layers.convolutional.Conv2D object at 0x0000027E43F5A3C8>>: AssertionError: Bad argument number for Name: 3, expecting 4\n",
      "WARNING: Entity <bound method Conv.call of <tensorflow.python.layers.convolutional.Conv2D object at 0x0000027E43F5A3C8>> could not be transformed and will be executed as-is. Please report this to the AutgoGraph team. When filing the bug, set the verbosity to 10 (on Linux, `export AUTOGRAPH_VERBOSITY=10`) and attach the full output. Cause: converting <bound method Conv.call of <tensorflow.python.layers.convolutional.Conv2D object at 0x0000027E43F5A3C8>>: AssertionError: Bad argument number for Name: 3, expecting 4\n",
      "WARNING:tensorflow:Entity <bound method Conv.call of <tensorflow.python.layers.convolutional.Conv2D object at 0x0000027E43F5AAC8>> could not be transformed and will be executed as-is. Please report this to the AutgoGraph team. When filing the bug, set the verbosity to 10 (on Linux, `export AUTOGRAPH_VERBOSITY=10`) and attach the full output. Cause: converting <bound method Conv.call of <tensorflow.python.layers.convolutional.Conv2D object at 0x0000027E43F5AAC8>>: AssertionError: Bad argument number for Name: 3, expecting 4\n",
      "WARNING: Entity <bound method Conv.call of <tensorflow.python.layers.convolutional.Conv2D object at 0x0000027E43F5AAC8>> could not be transformed and will be executed as-is. Please report this to the AutgoGraph team. When filing the bug, set the verbosity to 10 (on Linux, `export AUTOGRAPH_VERBOSITY=10`) and attach the full output. Cause: converting <bound method Conv.call of <tensorflow.python.layers.convolutional.Conv2D object at 0x0000027E43F5AAC8>>: AssertionError: Bad argument number for Name: 3, expecting 4\n",
      "WARNING:tensorflow:Entity <bound method Conv.call of <tensorflow.python.layers.convolutional.Conv2D object at 0x0000027E46736780>> could not be transformed and will be executed as-is. Please report this to the AutgoGraph team. When filing the bug, set the verbosity to 10 (on Linux, `export AUTOGRAPH_VERBOSITY=10`) and attach the full output. Cause: converting <bound method Conv.call of <tensorflow.python.layers.convolutional.Conv2D object at 0x0000027E46736780>>: AssertionError: Bad argument number for Name: 3, expecting 4\n",
      "WARNING: Entity <bound method Conv.call of <tensorflow.python.layers.convolutional.Conv2D object at 0x0000027E46736780>> could not be transformed and will be executed as-is. Please report this to the AutgoGraph team. When filing the bug, set the verbosity to 10 (on Linux, `export AUTOGRAPH_VERBOSITY=10`) and attach the full output. Cause: converting <bound method Conv.call of <tensorflow.python.layers.convolutional.Conv2D object at 0x0000027E46736780>>: AssertionError: Bad argument number for Name: 3, expecting 4\n",
      "WARNING:tensorflow:Entity <bound method Conv.call of <tensorflow.python.layers.convolutional.Conv2D object at 0x0000027E47AFDF28>> could not be transformed and will be executed as-is. Please report this to the AutgoGraph team. When filing the bug, set the verbosity to 10 (on Linux, `export AUTOGRAPH_VERBOSITY=10`) and attach the full output. Cause: converting <bound method Conv.call of <tensorflow.python.layers.convolutional.Conv2D object at 0x0000027E47AFDF28>>: AssertionError: Bad argument number for Name: 3, expecting 4\n",
      "WARNING: Entity <bound method Conv.call of <tensorflow.python.layers.convolutional.Conv2D object at 0x0000027E47AFDF28>> could not be transformed and will be executed as-is. Please report this to the AutgoGraph team. When filing the bug, set the verbosity to 10 (on Linux, `export AUTOGRAPH_VERBOSITY=10`) and attach the full output. Cause: converting <bound method Conv.call of <tensorflow.python.layers.convolutional.Conv2D object at 0x0000027E47AFDF28>>: AssertionError: Bad argument number for Name: 3, expecting 4\n",
      "WARNING:tensorflow:Entity <bound method Conv.call of <tensorflow.python.layers.convolutional.Conv2D object at 0x0000027E4463E780>> could not be transformed and will be executed as-is. Please report this to the AutgoGraph team. When filing the bug, set the verbosity to 10 (on Linux, `export AUTOGRAPH_VERBOSITY=10`) and attach the full output. Cause: converting <bound method Conv.call of <tensorflow.python.layers.convolutional.Conv2D object at 0x0000027E4463E780>>: AssertionError: Bad argument number for Name: 3, expecting 4\n",
      "WARNING: Entity <bound method Conv.call of <tensorflow.python.layers.convolutional.Conv2D object at 0x0000027E4463E780>> could not be transformed and will be executed as-is. Please report this to the AutgoGraph team. When filing the bug, set the verbosity to 10 (on Linux, `export AUTOGRAPH_VERBOSITY=10`) and attach the full output. Cause: converting <bound method Conv.call of <tensorflow.python.layers.convolutional.Conv2D object at 0x0000027E4463E780>>: AssertionError: Bad argument number for Name: 3, expecting 4\n",
      "WARNING:tensorflow:Entity <bound method Conv.call of <tensorflow.python.layers.convolutional.Conv2D object at 0x0000027E46739898>> could not be transformed and will be executed as-is. Please report this to the AutgoGraph team. When filing the bug, set the verbosity to 10 (on Linux, `export AUTOGRAPH_VERBOSITY=10`) and attach the full output. Cause: converting <bound method Conv.call of <tensorflow.python.layers.convolutional.Conv2D object at 0x0000027E46739898>>: AssertionError: Bad argument number for Name: 3, expecting 4\n",
      "WARNING: Entity <bound method Conv.call of <tensorflow.python.layers.convolutional.Conv2D object at 0x0000027E46739898>> could not be transformed and will be executed as-is. Please report this to the AutgoGraph team. When filing the bug, set the verbosity to 10 (on Linux, `export AUTOGRAPH_VERBOSITY=10`) and attach the full output. Cause: converting <bound method Conv.call of <tensorflow.python.layers.convolutional.Conv2D object at 0x0000027E46739898>>: AssertionError: Bad argument number for Name: 3, expecting 4\n",
      "WARNING:tensorflow:Entity <bound method Conv.call of <tensorflow.python.layers.convolutional.Conv2D object at 0x0000027E46739F28>> could not be transformed and will be executed as-is. Please report this to the AutgoGraph team. When filing the bug, set the verbosity to 10 (on Linux, `export AUTOGRAPH_VERBOSITY=10`) and attach the full output. Cause: converting <bound method Conv.call of <tensorflow.python.layers.convolutional.Conv2D object at 0x0000027E46739F28>>: AssertionError: Bad argument number for Name: 3, expecting 4\n",
      "WARNING: Entity <bound method Conv.call of <tensorflow.python.layers.convolutional.Conv2D object at 0x0000027E46739F28>> could not be transformed and will be executed as-is. Please report this to the AutgoGraph team. When filing the bug, set the verbosity to 10 (on Linux, `export AUTOGRAPH_VERBOSITY=10`) and attach the full output. Cause: converting <bound method Conv.call of <tensorflow.python.layers.convolutional.Conv2D object at 0x0000027E46739F28>>: AssertionError: Bad argument number for Name: 3, expecting 4\n",
      "WARNING:tensorflow:Entity <bound method Conv.call of <tensorflow.python.layers.convolutional.Conv2D object at 0x0000027E46739F28>> could not be transformed and will be executed as-is. Please report this to the AutgoGraph team. When filing the bug, set the verbosity to 10 (on Linux, `export AUTOGRAPH_VERBOSITY=10`) and attach the full output. Cause: converting <bound method Conv.call of <tensorflow.python.layers.convolutional.Conv2D object at 0x0000027E46739F28>>: AssertionError: Bad argument number for Name: 3, expecting 4\n",
      "WARNING: Entity <bound method Conv.call of <tensorflow.python.layers.convolutional.Conv2D object at 0x0000027E46739F28>> could not be transformed and will be executed as-is. Please report this to the AutgoGraph team. When filing the bug, set the verbosity to 10 (on Linux, `export AUTOGRAPH_VERBOSITY=10`) and attach the full output. Cause: converting <bound method Conv.call of <tensorflow.python.layers.convolutional.Conv2D object at 0x0000027E46739F28>>: AssertionError: Bad argument number for Name: 3, expecting 4\n",
      "WARNING:tensorflow:Entity <bound method Conv.call of <tensorflow.python.layers.convolutional.Conv2D object at 0x0000027E46739AC8>> could not be transformed and will be executed as-is. Please report this to the AutgoGraph team. When filing the bug, set the verbosity to 10 (on Linux, `export AUTOGRAPH_VERBOSITY=10`) and attach the full output. Cause: converting <bound method Conv.call of <tensorflow.python.layers.convolutional.Conv2D object at 0x0000027E46739AC8>>: AssertionError: Bad argument number for Name: 3, expecting 4\n",
      "WARNING: Entity <bound method Conv.call of <tensorflow.python.layers.convolutional.Conv2D object at 0x0000027E46739AC8>> could not be transformed and will be executed as-is. Please report this to the AutgoGraph team. When filing the bug, set the verbosity to 10 (on Linux, `export AUTOGRAPH_VERBOSITY=10`) and attach the full output. Cause: converting <bound method Conv.call of <tensorflow.python.layers.convolutional.Conv2D object at 0x0000027E46739AC8>>: AssertionError: Bad argument number for Name: 3, expecting 4\n",
      "WARNING:tensorflow:Entity <bound method Conv.call of <tensorflow.python.layers.convolutional.Conv2D object at 0x0000027E46739AC8>> could not be transformed and will be executed as-is. Please report this to the AutgoGraph team. When filing the bug, set the verbosity to 10 (on Linux, `export AUTOGRAPH_VERBOSITY=10`) and attach the full output. Cause: converting <bound method Conv.call of <tensorflow.python.layers.convolutional.Conv2D object at 0x0000027E46739AC8>>: AssertionError: Bad argument number for Name: 3, expecting 4\n",
      "WARNING: Entity <bound method Conv.call of <tensorflow.python.layers.convolutional.Conv2D object at 0x0000027E46739AC8>> could not be transformed and will be executed as-is. Please report this to the AutgoGraph team. When filing the bug, set the verbosity to 10 (on Linux, `export AUTOGRAPH_VERBOSITY=10`) and attach the full output. Cause: converting <bound method Conv.call of <tensorflow.python.layers.convolutional.Conv2D object at 0x0000027E46739AC8>>: AssertionError: Bad argument number for Name: 3, expecting 4\n",
      "WARNING:tensorflow:Entity <bound method Flatten.call of <tensorflow.python.layers.core.Flatten object at 0x0000027E445CD908>> could not be transformed and will be executed as-is. Please report this to the AutgoGraph team. When filing the bug, set the verbosity to 10 (on Linux, `export AUTOGRAPH_VERBOSITY=10`) and attach the full output. Cause: converting <bound method Flatten.call of <tensorflow.python.layers.core.Flatten object at 0x0000027E445CD908>>: AttributeError: module 'gast' has no attribute 'Num'\n",
      "WARNING: Entity <bound method Flatten.call of <tensorflow.python.layers.core.Flatten object at 0x0000027E445CD908>> could not be transformed and will be executed as-is. Please report this to the AutgoGraph team. When filing the bug, set the verbosity to 10 (on Linux, `export AUTOGRAPH_VERBOSITY=10`) and attach the full output. Cause: converting <bound method Flatten.call of <tensorflow.python.layers.core.Flatten object at 0x0000027E445CD908>>: AttributeError: module 'gast' has no attribute 'Num'\n",
      "WARNING:tensorflow:Entity <bound method Flatten.call of <tensorflow.python.layers.core.Flatten object at 0x0000027E44B5BEF0>> could not be transformed and will be executed as-is. Please report this to the AutgoGraph team. When filing the bug, set the verbosity to 10 (on Linux, `export AUTOGRAPH_VERBOSITY=10`) and attach the full output. Cause: converting <bound method Flatten.call of <tensorflow.python.layers.core.Flatten object at 0x0000027E44B5BEF0>>: AttributeError: module 'gast' has no attribute 'Num'\n",
      "WARNING: Entity <bound method Flatten.call of <tensorflow.python.layers.core.Flatten object at 0x0000027E44B5BEF0>> could not be transformed and will be executed as-is. Please report this to the AutgoGraph team. When filing the bug, set the verbosity to 10 (on Linux, `export AUTOGRAPH_VERBOSITY=10`) and attach the full output. Cause: converting <bound method Flatten.call of <tensorflow.python.layers.core.Flatten object at 0x0000027E44B5BEF0>>: AttributeError: module 'gast' has no attribute 'Num'\n",
      "WARNING:tensorflow:Entity <bound method Conv.call of <tensorflow.python.layers.convolutional.Conv2D object at 0x0000027E4685A588>> could not be transformed and will be executed as-is. Please report this to the AutgoGraph team. When filing the bug, set the verbosity to 10 (on Linux, `export AUTOGRAPH_VERBOSITY=10`) and attach the full output. Cause: converting <bound method Conv.call of <tensorflow.python.layers.convolutional.Conv2D object at 0x0000027E4685A588>>: AssertionError: Bad argument number for Name: 3, expecting 4\n",
      "WARNING: Entity <bound method Conv.call of <tensorflow.python.layers.convolutional.Conv2D object at 0x0000027E4685A588>> could not be transformed and will be executed as-is. Please report this to the AutgoGraph team. When filing the bug, set the verbosity to 10 (on Linux, `export AUTOGRAPH_VERBOSITY=10`) and attach the full output. Cause: converting <bound method Conv.call of <tensorflow.python.layers.convolutional.Conv2D object at 0x0000027E4685A588>>: AssertionError: Bad argument number for Name: 3, expecting 4\n",
      "WARNING:tensorflow:Entity <bound method Flatten.call of <tensorflow.python.layers.core.Flatten object at 0x0000027E4CA502B0>> could not be transformed and will be executed as-is. Please report this to the AutgoGraph team. When filing the bug, set the verbosity to 10 (on Linux, `export AUTOGRAPH_VERBOSITY=10`) and attach the full output. Cause: converting <bound method Flatten.call of <tensorflow.python.layers.core.Flatten object at 0x0000027E4CA502B0>>: AttributeError: module 'gast' has no attribute 'Num'\n",
      "WARNING: Entity <bound method Flatten.call of <tensorflow.python.layers.core.Flatten object at 0x0000027E4CA502B0>> could not be transformed and will be executed as-is. Please report this to the AutgoGraph team. When filing the bug, set the verbosity to 10 (on Linux, `export AUTOGRAPH_VERBOSITY=10`) and attach the full output. Cause: converting <bound method Flatten.call of <tensorflow.python.layers.core.Flatten object at 0x0000027E4CA502B0>>: AttributeError: module 'gast' has no attribute 'Num'\n",
      "WARNING:tensorflow:Entity <bound method Dense.call of <tensorflow.python.layers.core.Dense object at 0x0000027E4CA50DA0>> could not be transformed and will be executed as-is. Please report this to the AutgoGraph team. When filing the bug, set the verbosity to 10 (on Linux, `export AUTOGRAPH_VERBOSITY=10`) and attach the full output. Cause: converting <bound method Dense.call of <tensorflow.python.layers.core.Dense object at 0x0000027E4CA50DA0>>: AssertionError: Bad argument number for Name: 3, expecting 4\n",
      "WARNING: Entity <bound method Dense.call of <tensorflow.python.layers.core.Dense object at 0x0000027E4CA50DA0>> could not be transformed and will be executed as-is. Please report this to the AutgoGraph team. When filing the bug, set the verbosity to 10 (on Linux, `export AUTOGRAPH_VERBOSITY=10`) and attach the full output. Cause: converting <bound method Dense.call of <tensorflow.python.layers.core.Dense object at 0x0000027E4CA50DA0>>: AssertionError: Bad argument number for Name: 3, expecting 4\n",
      "WARNING:tensorflow:Entity <bound method Flatten.call of <tensorflow.python.layers.core.Flatten object at 0x0000027E4CA50400>> could not be transformed and will be executed as-is. Please report this to the AutgoGraph team. When filing the bug, set the verbosity to 10 (on Linux, `export AUTOGRAPH_VERBOSITY=10`) and attach the full output. Cause: converting <bound method Flatten.call of <tensorflow.python.layers.core.Flatten object at 0x0000027E4CA50400>>: AttributeError: module 'gast' has no attribute 'Num'\n",
      "WARNING: Entity <bound method Flatten.call of <tensorflow.python.layers.core.Flatten object at 0x0000027E4CA50400>> could not be transformed and will be executed as-is. Please report this to the AutgoGraph team. When filing the bug, set the verbosity to 10 (on Linux, `export AUTOGRAPH_VERBOSITY=10`) and attach the full output. Cause: converting <bound method Flatten.call of <tensorflow.python.layers.core.Flatten object at 0x0000027E4CA50400>>: AttributeError: module 'gast' has no attribute 'Num'\n",
      "WARNING:tensorflow:Entity <bound method Dense.call of <tensorflow.python.layers.core.Dense object at 0x0000027E4CA50B38>> could not be transformed and will be executed as-is. Please report this to the AutgoGraph team. When filing the bug, set the verbosity to 10 (on Linux, `export AUTOGRAPH_VERBOSITY=10`) and attach the full output. Cause: converting <bound method Dense.call of <tensorflow.python.layers.core.Dense object at 0x0000027E4CA50B38>>: AssertionError: Bad argument number for Name: 3, expecting 4\n",
      "WARNING: Entity <bound method Dense.call of <tensorflow.python.layers.core.Dense object at 0x0000027E4CA50B38>> could not be transformed and will be executed as-is. Please report this to the AutgoGraph team. When filing the bug, set the verbosity to 10 (on Linux, `export AUTOGRAPH_VERBOSITY=10`) and attach the full output. Cause: converting <bound method Dense.call of <tensorflow.python.layers.core.Dense object at 0x0000027E4CA50B38>>: AssertionError: Bad argument number for Name: 3, expecting 4\n",
      "WARNING:tensorflow:Entity <bound method Flatten.call of <tensorflow.python.layers.core.Flatten object at 0x0000027E4CA50710>> could not be transformed and will be executed as-is. Please report this to the AutgoGraph team. When filing the bug, set the verbosity to 10 (on Linux, `export AUTOGRAPH_VERBOSITY=10`) and attach the full output. Cause: converting <bound method Flatten.call of <tensorflow.python.layers.core.Flatten object at 0x0000027E4CA50710>>: AttributeError: module 'gast' has no attribute 'Num'\n",
      "WARNING: Entity <bound method Flatten.call of <tensorflow.python.layers.core.Flatten object at 0x0000027E4CA50710>> could not be transformed and will be executed as-is. Please report this to the AutgoGraph team. When filing the bug, set the verbosity to 10 (on Linux, `export AUTOGRAPH_VERBOSITY=10`) and attach the full output. Cause: converting <bound method Flatten.call of <tensorflow.python.layers.core.Flatten object at 0x0000027E4CA50710>>: AttributeError: module 'gast' has no attribute 'Num'\n",
      "WARNING:tensorflow:Entity <bound method Dense.call of <tensorflow.python.layers.core.Dense object at 0x0000027E4CA50780>> could not be transformed and will be executed as-is. Please report this to the AutgoGraph team. When filing the bug, set the verbosity to 10 (on Linux, `export AUTOGRAPH_VERBOSITY=10`) and attach the full output. Cause: converting <bound method Dense.call of <tensorflow.python.layers.core.Dense object at 0x0000027E4CA50780>>: AssertionError: Bad argument number for Name: 3, expecting 4\n",
      "WARNING: Entity <bound method Dense.call of <tensorflow.python.layers.core.Dense object at 0x0000027E4CA50780>> could not be transformed and will be executed as-is. Please report this to the AutgoGraph team. When filing the bug, set the verbosity to 10 (on Linux, `export AUTOGRAPH_VERBOSITY=10`) and attach the full output. Cause: converting <bound method Dense.call of <tensorflow.python.layers.core.Dense object at 0x0000027E4CA50780>>: AssertionError: Bad argument number for Name: 3, expecting 4\n",
      "WARNING:tensorflow:Entity <bound method Flatten.call of <tensorflow.python.layers.core.Flatten object at 0x0000027E4CA50B70>> could not be transformed and will be executed as-is. Please report this to the AutgoGraph team. When filing the bug, set the verbosity to 10 (on Linux, `export AUTOGRAPH_VERBOSITY=10`) and attach the full output. Cause: converting <bound method Flatten.call of <tensorflow.python.layers.core.Flatten object at 0x0000027E4CA50B70>>: AttributeError: module 'gast' has no attribute 'Num'\n",
      "WARNING: Entity <bound method Flatten.call of <tensorflow.python.layers.core.Flatten object at 0x0000027E4CA50B70>> could not be transformed and will be executed as-is. Please report this to the AutgoGraph team. When filing the bug, set the verbosity to 10 (on Linux, `export AUTOGRAPH_VERBOSITY=10`) and attach the full output. Cause: converting <bound method Flatten.call of <tensorflow.python.layers.core.Flatten object at 0x0000027E4CA50B70>>: AttributeError: module 'gast' has no attribute 'Num'\n",
      "WARNING:tensorflow:Entity <bound method Dense.call of <tensorflow.python.layers.core.Dense object at 0x0000027E4CA507F0>> could not be transformed and will be executed as-is. Please report this to the AutgoGraph team. When filing the bug, set the verbosity to 10 (on Linux, `export AUTOGRAPH_VERBOSITY=10`) and attach the full output. Cause: converting <bound method Dense.call of <tensorflow.python.layers.core.Dense object at 0x0000027E4CA507F0>>: AssertionError: Bad argument number for Name: 3, expecting 4\n",
      "WARNING: Entity <bound method Dense.call of <tensorflow.python.layers.core.Dense object at 0x0000027E4CA507F0>> could not be transformed and will be executed as-is. Please report this to the AutgoGraph team. When filing the bug, set the verbosity to 10 (on Linux, `export AUTOGRAPH_VERBOSITY=10`) and attach the full output. Cause: converting <bound method Dense.call of <tensorflow.python.layers.core.Dense object at 0x0000027E4CA507F0>>: AssertionError: Bad argument number for Name: 3, expecting 4\n",
      "WARNING:tensorflow:Entity <bound method Conv.call of <tensorflow.python.layers.convolutional.Conv2D object at 0x0000027E4809DDA0>> could not be transformed and will be executed as-is. Please report this to the AutgoGraph team. When filing the bug, set the verbosity to 10 (on Linux, `export AUTOGRAPH_VERBOSITY=10`) and attach the full output. Cause: converting <bound method Conv.call of <tensorflow.python.layers.convolutional.Conv2D object at 0x0000027E4809DDA0>>: AssertionError: Bad argument number for Name: 3, expecting 4\n",
      "WARNING: Entity <bound method Conv.call of <tensorflow.python.layers.convolutional.Conv2D object at 0x0000027E4809DDA0>> could not be transformed and will be executed as-is. Please report this to the AutgoGraph team. When filing the bug, set the verbosity to 10 (on Linux, `export AUTOGRAPH_VERBOSITY=10`) and attach the full output. Cause: converting <bound method Conv.call of <tensorflow.python.layers.convolutional.Conv2D object at 0x0000027E4809DDA0>>: AssertionError: Bad argument number for Name: 3, expecting 4\n",
      "WARNING:tensorflow:Entity <bound method Conv.call of <tensorflow.python.layers.convolutional.Conv2D object at 0x0000027E4809DC88>> could not be transformed and will be executed as-is. Please report this to the AutgoGraph team. When filing the bug, set the verbosity to 10 (on Linux, `export AUTOGRAPH_VERBOSITY=10`) and attach the full output. Cause: converting <bound method Conv.call of <tensorflow.python.layers.convolutional.Conv2D object at 0x0000027E4809DC88>>: AssertionError: Bad argument number for Name: 3, expecting 4\n",
      "WARNING: Entity <bound method Conv.call of <tensorflow.python.layers.convolutional.Conv2D object at 0x0000027E4809DC88>> could not be transformed and will be executed as-is. Please report this to the AutgoGraph team. When filing the bug, set the verbosity to 10 (on Linux, `export AUTOGRAPH_VERBOSITY=10`) and attach the full output. Cause: converting <bound method Conv.call of <tensorflow.python.layers.convolutional.Conv2D object at 0x0000027E4809DC88>>: AssertionError: Bad argument number for Name: 3, expecting 4\n",
      "WARNING:tensorflow:Entity <bound method Conv.call of <tensorflow.python.layers.convolutional.Conv2D object at 0x0000027E4809DCC0>> could not be transformed and will be executed as-is. Please report this to the AutgoGraph team. When filing the bug, set the verbosity to 10 (on Linux, `export AUTOGRAPH_VERBOSITY=10`) and attach the full output. Cause: converting <bound method Conv.call of <tensorflow.python.layers.convolutional.Conv2D object at 0x0000027E4809DCC0>>: AssertionError: Bad argument number for Name: 3, expecting 4\n",
      "WARNING: Entity <bound method Conv.call of <tensorflow.python.layers.convolutional.Conv2D object at 0x0000027E4809DCC0>> could not be transformed and will be executed as-is. Please report this to the AutgoGraph team. When filing the bug, set the verbosity to 10 (on Linux, `export AUTOGRAPH_VERBOSITY=10`) and attach the full output. Cause: converting <bound method Conv.call of <tensorflow.python.layers.convolutional.Conv2D object at 0x0000027E4809DCC0>>: AssertionError: Bad argument number for Name: 3, expecting 4\n",
      "WARNING:tensorflow:Entity <bound method Conv.call of <tensorflow.python.layers.convolutional.Conv2D object at 0x0000027E4662C3C8>> could not be transformed and will be executed as-is. Please report this to the AutgoGraph team. When filing the bug, set the verbosity to 10 (on Linux, `export AUTOGRAPH_VERBOSITY=10`) and attach the full output. Cause: converting <bound method Conv.call of <tensorflow.python.layers.convolutional.Conv2D object at 0x0000027E4662C3C8>>: AssertionError: Bad argument number for Name: 3, expecting 4\n",
      "WARNING: Entity <bound method Conv.call of <tensorflow.python.layers.convolutional.Conv2D object at 0x0000027E4662C3C8>> could not be transformed and will be executed as-is. Please report this to the AutgoGraph team. When filing the bug, set the verbosity to 10 (on Linux, `export AUTOGRAPH_VERBOSITY=10`) and attach the full output. Cause: converting <bound method Conv.call of <tensorflow.python.layers.convolutional.Conv2D object at 0x0000027E4662C3C8>>: AssertionError: Bad argument number for Name: 3, expecting 4\n",
      "WARNING:tensorflow:Entity <bound method Conv.call of <tensorflow.python.layers.convolutional.Conv2D object at 0x0000027E46546748>> could not be transformed and will be executed as-is. Please report this to the AutgoGraph team. When filing the bug, set the verbosity to 10 (on Linux, `export AUTOGRAPH_VERBOSITY=10`) and attach the full output. Cause: converting <bound method Conv.call of <tensorflow.python.layers.convolutional.Conv2D object at 0x0000027E46546748>>: AssertionError: Bad argument number for Name: 3, expecting 4\n",
      "WARNING: Entity <bound method Conv.call of <tensorflow.python.layers.convolutional.Conv2D object at 0x0000027E46546748>> could not be transformed and will be executed as-is. Please report this to the AutgoGraph team. When filing the bug, set the verbosity to 10 (on Linux, `export AUTOGRAPH_VERBOSITY=10`) and attach the full output. Cause: converting <bound method Conv.call of <tensorflow.python.layers.convolutional.Conv2D object at 0x0000027E46546748>>: AssertionError: Bad argument number for Name: 3, expecting 4\n",
      "WARNING:tensorflow:Entity <bound method Conv.call of <tensorflow.python.layers.convolutional.Conv2D object at 0x0000027E445097B8>> could not be transformed and will be executed as-is. Please report this to the AutgoGraph team. When filing the bug, set the verbosity to 10 (on Linux, `export AUTOGRAPH_VERBOSITY=10`) and attach the full output. Cause: converting <bound method Conv.call of <tensorflow.python.layers.convolutional.Conv2D object at 0x0000027E445097B8>>: AssertionError: Bad argument number for Name: 3, expecting 4\n",
      "WARNING: Entity <bound method Conv.call of <tensorflow.python.layers.convolutional.Conv2D object at 0x0000027E445097B8>> could not be transformed and will be executed as-is. Please report this to the AutgoGraph team. When filing the bug, set the verbosity to 10 (on Linux, `export AUTOGRAPH_VERBOSITY=10`) and attach the full output. Cause: converting <bound method Conv.call of <tensorflow.python.layers.convolutional.Conv2D object at 0x0000027E445097B8>>: AssertionError: Bad argument number for Name: 3, expecting 4\n",
      "WARNING:tensorflow:Entity <bound method Conv.call of <tensorflow.python.layers.convolutional.Conv2D object at 0x0000027E4CA50780>> could not be transformed and will be executed as-is. Please report this to the AutgoGraph team. When filing the bug, set the verbosity to 10 (on Linux, `export AUTOGRAPH_VERBOSITY=10`) and attach the full output. Cause: converting <bound method Conv.call of <tensorflow.python.layers.convolutional.Conv2D object at 0x0000027E4CA50780>>: AssertionError: Bad argument number for Name: 3, expecting 4\n",
      "WARNING: Entity <bound method Conv.call of <tensorflow.python.layers.convolutional.Conv2D object at 0x0000027E4CA50780>> could not be transformed and will be executed as-is. Please report this to the AutgoGraph team. When filing the bug, set the verbosity to 10 (on Linux, `export AUTOGRAPH_VERBOSITY=10`) and attach the full output. Cause: converting <bound method Conv.call of <tensorflow.python.layers.convolutional.Conv2D object at 0x0000027E4CA50780>>: AssertionError: Bad argument number for Name: 3, expecting 4\n",
      "WARNING:tensorflow:Entity <bound method Conv.call of <tensorflow.python.layers.convolutional.Conv2D object at 0x0000027E442B4FD0>> could not be transformed and will be executed as-is. Please report this to the AutgoGraph team. When filing the bug, set the verbosity to 10 (on Linux, `export AUTOGRAPH_VERBOSITY=10`) and attach the full output. Cause: converting <bound method Conv.call of <tensorflow.python.layers.convolutional.Conv2D object at 0x0000027E442B4FD0>>: AssertionError: Bad argument number for Name: 3, expecting 4\n",
      "WARNING: Entity <bound method Conv.call of <tensorflow.python.layers.convolutional.Conv2D object at 0x0000027E442B4FD0>> could not be transformed and will be executed as-is. Please report this to the AutgoGraph team. When filing the bug, set the verbosity to 10 (on Linux, `export AUTOGRAPH_VERBOSITY=10`) and attach the full output. Cause: converting <bound method Conv.call of <tensorflow.python.layers.convolutional.Conv2D object at 0x0000027E442B4FD0>>: AssertionError: Bad argument number for Name: 3, expecting 4\n",
      "WARNING:tensorflow:Entity <bound method Conv.call of <tensorflow.python.layers.convolutional.Conv2D object at 0x0000027E444936A0>> could not be transformed and will be executed as-is. Please report this to the AutgoGraph team. When filing the bug, set the verbosity to 10 (on Linux, `export AUTOGRAPH_VERBOSITY=10`) and attach the full output. Cause: converting <bound method Conv.call of <tensorflow.python.layers.convolutional.Conv2D object at 0x0000027E444936A0>>: AssertionError: Bad argument number for Name: 3, expecting 4\n",
      "WARNING: Entity <bound method Conv.call of <tensorflow.python.layers.convolutional.Conv2D object at 0x0000027E444936A0>> could not be transformed and will be executed as-is. Please report this to the AutgoGraph team. When filing the bug, set the verbosity to 10 (on Linux, `export AUTOGRAPH_VERBOSITY=10`) and attach the full output. Cause: converting <bound method Conv.call of <tensorflow.python.layers.convolutional.Conv2D object at 0x0000027E444936A0>>: AssertionError: Bad argument number for Name: 3, expecting 4\n",
      "WARNING:tensorflow:Entity <bound method Conv.call of <tensorflow.python.layers.convolutional.Conv2D object at 0x0000027E46546748>> could not be transformed and will be executed as-is. Please report this to the AutgoGraph team. When filing the bug, set the verbosity to 10 (on Linux, `export AUTOGRAPH_VERBOSITY=10`) and attach the full output. Cause: converting <bound method Conv.call of <tensorflow.python.layers.convolutional.Conv2D object at 0x0000027E46546748>>: AssertionError: Bad argument number for Name: 3, expecting 4\n",
      "WARNING: Entity <bound method Conv.call of <tensorflow.python.layers.convolutional.Conv2D object at 0x0000027E46546748>> could not be transformed and will be executed as-is. Please report this to the AutgoGraph team. When filing the bug, set the verbosity to 10 (on Linux, `export AUTOGRAPH_VERBOSITY=10`) and attach the full output. Cause: converting <bound method Conv.call of <tensorflow.python.layers.convolutional.Conv2D object at 0x0000027E46546748>>: AssertionError: Bad argument number for Name: 3, expecting 4\n",
      "WARNING:tensorflow:Entity <bound method Conv.call of <tensorflow.python.layers.convolutional.Conv2D object at 0x0000027E46546748>> could not be transformed and will be executed as-is. Please report this to the AutgoGraph team. When filing the bug, set the verbosity to 10 (on Linux, `export AUTOGRAPH_VERBOSITY=10`) and attach the full output. Cause: converting <bound method Conv.call of <tensorflow.python.layers.convolutional.Conv2D object at 0x0000027E46546748>>: AssertionError: Bad argument number for Name: 3, expecting 4\n",
      "WARNING: Entity <bound method Conv.call of <tensorflow.python.layers.convolutional.Conv2D object at 0x0000027E46546748>> could not be transformed and will be executed as-is. Please report this to the AutgoGraph team. When filing the bug, set the verbosity to 10 (on Linux, `export AUTOGRAPH_VERBOSITY=10`) and attach the full output. Cause: converting <bound method Conv.call of <tensorflow.python.layers.convolutional.Conv2D object at 0x0000027E46546748>>: AssertionError: Bad argument number for Name: 3, expecting 4\n",
      "INFO:tensorflow:loading latest checkpoint file: ./pretrained_model/checkpoint/UGATIT_light_selfie2anime_lsgan_4resblock_6dis_1_1_10_10_1000_sn_smoothing\\UGATIT_light.model-214000\n",
      "INFO:tensorflow:Restoring parameters from ./pretrained_model/checkpoint/UGATIT_light_selfie2anime_lsgan_4resblock_6dis_1_1_10_10_1000_sn_smoothing\\UGATIT_light.model-214000\n",
      "INFO:tensorflow:Assets added to graph.\n",
      "INFO:tensorflow:No assets to write.\n",
      "INFO:tensorflow:SavedModel written to: ./saved_model\\saved_model.pb\n"
     ]
    }
   ],
   "source": [
    "saved_model_dir = './saved_model'\n",
    "\n",
    "with tf.Graph().as_default(), tf.Session() as sess:\n",
    "    gan = UGATIT(sess, data)\n",
    "    gan.build_model()\n",
    "    load_checkpoint(sess, './pretrained_model/checkpoint/UGATIT_light_selfie2anime_lsgan_4resblock_6dis_1_1_10_10_1000_sn_smoothing')\n",
    "    \n",
    "    # Write SavedModel for serving or conversion to TF Lite\n",
    "    # At this point, creating the SavedModel needs only a matter \n",
    "    # of a few keystrokes. Remember that we are still under the Session context.\n",
    "    tf.saved_model.simple_save(\n",
    "        sess,\n",
    "        saved_model_dir,\n",
    "        inputs={\n",
    "            gan.test_domain_A.name: gan.test_domain_A,\n",
    "        },\n",
    "        outputs={gan.test_fake_B.name: gan.test_fake_B})\n",
    "    tf.logging.debug('Export transform SavedModel to',\n",
    "                     saved_model_dir)"
   ]
  },
  {
   "cell_type": "markdown",
   "metadata": {
    "colab_type": "text",
    "id": "4zZLimW7Yrl8"
   },
   "source": [
    "Note the path of the `SavedModel` from the above logs. We will be needing this for the subsequent steps. The warnings can be ignored. "
   ]
  },
  {
   "cell_type": "code",
   "execution_count": 9,
   "metadata": {
    "colab": {
     "base_uri": "https://localhost:8080/",
     "height": 34
    },
    "colab_type": "code",
    "id": "C0cRUvr6Yehj",
    "outputId": "76b23b46-63ca-4b56-cd97-32ccd1fef6d1"
   },
   "outputs": [
    {
     "name": "stdout",
     "output_type": "stream",
     "text": [
      "836461\n"
     ]
    }
   ],
   "source": [
    "# Inspecting model size\n",
    "print(os.path.getsize(os.path.join(saved_model_dir, 'saved_model.pb')))"
   ]
  }
 ],
 "metadata": {
  "colab": {
   "collapsed_sections": [],
   "name": "Selfie2Anime_Model_Conversion.ipynb",
   "provenance": []
  },
  "kernelspec": {
   "display_name": ".venv",
   "language": "python",
   "name": "python3"
  },
  "language_info": {
   "codemirror_mode": {
    "name": "ipython",
    "version": 3
   },
   "file_extension": ".py",
   "mimetype": "text/x-python",
   "name": "python",
   "nbconvert_exporter": "python",
   "pygments_lexer": "ipython3",
   "version": "3.6.8"
  }
 },
 "nbformat": 4,
 "nbformat_minor": 1
}
